<?xml version="1.0" encoding="UTF-8"?>
<testng-results skipped="0" failed="5" total="5" passed="0">
  <reporter-output>
  </reporter-output>
  <suite name="Default suite" duration-ms="30474" started-at="2016-12-29T10:57:35Z" finished-at="2016-12-29T10:58:05Z">
    <groups>
    </groups>
    <test name="Default test" duration-ms="30474" started-at="2016-12-29T10:57:35Z" finished-at="2016-12-29T10:58:05Z">
      <class name="com.example.tests.ContactCreationTests">
        <test-method status="PASS" signature="setUp()[pri:0, instance:com.example.tests.ContactCreationTests@7c0e2abd]" name="setUp" is-config="true" duration-ms="6266" started-at="2016-12-29T13:57:35Z" finished-at="2016-12-29T13:57:41Z">
          <reporter-output>
          </reporter-output>
        </test-method> <!-- setUp -->
        <test-method status="FAIL" signature="testContactCreationWithValidData(com.example.tests.ContactData)[pri:0, instance:com.example.tests.ContactCreationTests@7c0e2abd]" name="testContactCreationWithValidData" duration-ms="4914" started-at="2016-12-29T13:57:41Z" data-provider="randomValidContactGenerator" finished-at="2016-12-29T13:57:46Z">
          <params>
            <param index="0">
              <value>
                <![CDATA[ContactData [firstname=contact-1706345991]]]>
              </value>
            </param>
          </params>
          <exception class="java.lang.AssertionError">
            <message>
              <![CDATA[Lists differ at element [2]: ContactData [firstname=contact-1706345991] != ContactData [firstname=contact-1706345991 contact545397946] expected [ContactData [firstname=contact-1706345991]] but found [ContactData [firstname=contact-1706345991 contact545397946]]]]>
            </message>
            <full-stacktrace>
              <![CDATA[java.lang.AssertionError: Lists differ at element [2]: ContactData [firstname=contact-1706345991] != ContactData [firstname=contact-1706345991 contact545397946] expected [ContactData [firstname=contact-1706345991]] but found [ContactData [firstname=contact-1706345991 contact545397946]]
	at org.testng.Assert.fail(Assert.java:94)
	at org.testng.Assert.failNotEquals(Assert.java:496)
	at org.testng.Assert.assertEquals(Assert.java:125)
	at org.testng.Assert.assertEquals(Assert.java:551)
	at org.testng.Assert.assertEquals(Assert.java:516)
	at com.example.tests.ContactCreationTests.testContactCreationWithValidData(ContactCreationTests.java:75)
	at sun.reflect.NativeMethodAccessorImpl.invoke0(Native Method)
	at sun.reflect.NativeMethodAccessorImpl.invoke(Unknown Source)
	at sun.reflect.DelegatingMethodAccessorImpl.invoke(Unknown Source)
	at java.lang.reflect.Method.invoke(Unknown Source)
	at org.testng.internal.MethodInvocationHelper.invokeMethod(MethodInvocationHelper.java:85)
	at org.testng.internal.Invoker.invokeMethod(Invoker.java:639)
	at org.testng.internal.Invoker.invokeTestMethod(Invoker.java:816)
	at org.testng.internal.Invoker.invokeTestMethods(Invoker.java:1124)
	at org.testng.internal.TestMethodWorker.invokeTestMethods(TestMethodWorker.java:125)
	at org.testng.internal.TestMethodWorker.run(TestMethodWorker.java:108)
	at org.testng.TestRunner.privateRun(TestRunner.java:774)
	at org.testng.TestRunner.run(TestRunner.java:624)
	at org.testng.SuiteRunner.runTest(SuiteRunner.java:359)
	at org.testng.SuiteRunner.runSequentially(SuiteRunner.java:354)
	at org.testng.SuiteRunner.privateRun(SuiteRunner.java:312)
	at org.testng.SuiteRunner.run(SuiteRunner.java:261)
	at org.testng.SuiteRunnerWorker.runSuite(SuiteRunnerWorker.java:52)
	at org.testng.SuiteRunnerWorker.run(SuiteRunnerWorker.java:86)
	at org.testng.TestNG.runSuitesSequentially(TestNG.java:1215)
	at org.testng.TestNG.runSuitesLocally(TestNG.java:1140)
	at org.testng.TestNG.run(TestNG.java:1048)
	at org.testng.remote.AbstractRemoteTestNG.run(AbstractRemoteTestNG.java:132)
	at org.testng.remote.RemoteTestNG.initAndRun(RemoteTestNG.java:236)
	at org.testng.remote.RemoteTestNG.main(RemoteTestNG.java:81)
]]>
            </full-stacktrace>
          </exception> <!-- java.lang.AssertionError -->
          <reporter-output>
          </reporter-output>
        </test-method> <!-- testContactCreationWithValidData -->
        <test-method status="FAIL" signature="testContactCreationWithValidData(com.example.tests.ContactData)[pri:0, instance:com.example.tests.ContactCreationTests@7c0e2abd]" name="testContactCreationWithValidData" duration-ms="4466" started-at="2016-12-29T13:57:46Z" data-provider="randomValidContactGenerator" finished-at="2016-12-29T13:57:50Z">
          <params>
            <param index="0">
              <value>
                <![CDATA[ContactData [firstname=contact-1945750768]]]>
              </value>
            </param>
          </params>
          <exception class="java.lang.AssertionError">
            <message>
              <![CDATA[Lists differ at element [4]: ContactData [firstname=contact-1945750768] != ContactData [firstname=contact-1945750768 contact979009808] expected [ContactData [firstname=contact-1945750768]] but found [ContactData [firstname=contact-1945750768 contact979009808]]]]>
            </message>
            <full-stacktrace>
              <![CDATA[java.lang.AssertionError: Lists differ at element [4]: ContactData [firstname=contact-1945750768] != ContactData [firstname=contact-1945750768 contact979009808] expected [ContactData [firstname=contact-1945750768]] but found [ContactData [firstname=contact-1945750768 contact979009808]]
	at org.testng.Assert.fail(Assert.java:94)
	at org.testng.Assert.failNotEquals(Assert.java:496)
	at org.testng.Assert.assertEquals(Assert.java:125)
	at org.testng.Assert.assertEquals(Assert.java:551)
	at org.testng.Assert.assertEquals(Assert.java:516)
	at com.example.tests.ContactCreationTests.testContactCreationWithValidData(ContactCreationTests.java:75)
	at sun.reflect.NativeMethodAccessorImpl.invoke0(Native Method)
	at sun.reflect.NativeMethodAccessorImpl.invoke(Unknown Source)
	at sun.reflect.DelegatingMethodAccessorImpl.invoke(Unknown Source)
	at java.lang.reflect.Method.invoke(Unknown Source)
	at org.testng.internal.MethodInvocationHelper.invokeMethod(MethodInvocationHelper.java:85)
	at org.testng.internal.Invoker.invokeMethod(Invoker.java:639)
	at org.testng.internal.Invoker.invokeTestMethod(Invoker.java:816)
	at org.testng.internal.Invoker.invokeTestMethods(Invoker.java:1124)
	at org.testng.internal.TestMethodWorker.invokeTestMethods(TestMethodWorker.java:125)
	at org.testng.internal.TestMethodWorker.run(TestMethodWorker.java:108)
	at org.testng.TestRunner.privateRun(TestRunner.java:774)
	at org.testng.TestRunner.run(TestRunner.java:624)
	at org.testng.SuiteRunner.runTest(SuiteRunner.java:359)
	at org.testng.SuiteRunner.runSequentially(SuiteRunner.java:354)
	at org.testng.SuiteRunner.privateRun(SuiteRunner.java:312)
	at org.testng.SuiteRunner.run(SuiteRunner.java:261)
	at org.testng.SuiteRunnerWorker.runSuite(SuiteRunnerWorker.java:52)
	at org.testng.SuiteRunnerWorker.run(SuiteRunnerWorker.java:86)
	at org.testng.TestNG.runSuitesSequentially(TestNG.java:1215)
	at org.testng.TestNG.runSuitesLocally(TestNG.java:1140)
	at org.testng.TestNG.run(TestNG.java:1048)
	at org.testng.remote.AbstractRemoteTestNG.run(AbstractRemoteTestNG.java:132)
	at org.testng.remote.RemoteTestNG.initAndRun(RemoteTestNG.java:236)
	at org.testng.remote.RemoteTestNG.main(RemoteTestNG.java:81)
]]>
            </full-stacktrace>
          </exception> <!-- java.lang.AssertionError -->
          <reporter-output>
          </reporter-output>
        </test-method> <!-- testContactCreationWithValidData -->
        <test-method status="FAIL" signature="testContactCreationWithValidData(com.example.tests.ContactData)[pri:0, instance:com.example.tests.ContactCreationTests@7c0e2abd]" name="testContactCreationWithValidData" duration-ms="4639" started-at="2016-12-29T13:57:50Z" data-provider="randomValidContactGenerator" finished-at="2016-12-29T13:57:55Z">
          <params>
            <param index="0">
              <value>
                <![CDATA[ContactData [firstname=contact1652158582]]]>
              </value>
            </param>
          </params>
          <exception class="java.lang.AssertionError">
            <message>
              <![CDATA[Lists differ at element [6]: ContactData [firstname=contact1652158582] != ContactData [firstname=contact1652158582 contact1954725106] expected [ContactData [firstname=contact1652158582]] but found [ContactData [firstname=contact1652158582 contact1954725106]]]]>
            </message>
            <full-stacktrace>
              <![CDATA[java.lang.AssertionError: Lists differ at element [6]: ContactData [firstname=contact1652158582] != ContactData [firstname=contact1652158582 contact1954725106] expected [ContactData [firstname=contact1652158582]] but found [ContactData [firstname=contact1652158582 contact1954725106]]
	at org.testng.Assert.fail(Assert.java:94)
	at org.testng.Assert.failNotEquals(Assert.java:496)
	at org.testng.Assert.assertEquals(Assert.java:125)
	at org.testng.Assert.assertEquals(Assert.java:551)
	at org.testng.Assert.assertEquals(Assert.java:516)
	at com.example.tests.ContactCreationTests.testContactCreationWithValidData(ContactCreationTests.java:75)
	at sun.reflect.NativeMethodAccessorImpl.invoke0(Native Method)
	at sun.reflect.NativeMethodAccessorImpl.invoke(Unknown Source)
	at sun.reflect.DelegatingMethodAccessorImpl.invoke(Unknown Source)
	at java.lang.reflect.Method.invoke(Unknown Source)
	at org.testng.internal.MethodInvocationHelper.invokeMethod(MethodInvocationHelper.java:85)
	at org.testng.internal.Invoker.invokeMethod(Invoker.java:639)
	at org.testng.internal.Invoker.invokeTestMethod(Invoker.java:816)
	at org.testng.internal.Invoker.invokeTestMethods(Invoker.java:1124)
	at org.testng.internal.TestMethodWorker.invokeTestMethods(TestMethodWorker.java:125)
	at org.testng.internal.TestMethodWorker.run(TestMethodWorker.java:108)
	at org.testng.TestRunner.privateRun(TestRunner.java:774)
	at org.testng.TestRunner.run(TestRunner.java:624)
	at org.testng.SuiteRunner.runTest(SuiteRunner.java:359)
	at org.testng.SuiteRunner.runSequentially(SuiteRunner.java:354)
	at org.testng.SuiteRunner.privateRun(SuiteRunner.java:312)
	at org.testng.SuiteRunner.run(SuiteRunner.java:261)
	at org.testng.SuiteRunnerWorker.runSuite(SuiteRunnerWorker.java:52)
	at org.testng.SuiteRunnerWorker.run(SuiteRunnerWorker.java:86)
	at org.testng.TestNG.runSuitesSequentially(TestNG.java:1215)
	at org.testng.TestNG.runSuitesLocally(TestNG.java:1140)
	at org.testng.TestNG.run(TestNG.java:1048)
	at org.testng.remote.AbstractRemoteTestNG.run(AbstractRemoteTestNG.java:132)
	at org.testng.remote.RemoteTestNG.initAndRun(RemoteTestNG.java:236)
	at org.testng.remote.RemoteTestNG.main(RemoteTestNG.java:81)
]]>
            </full-stacktrace>
          </exception> <!-- java.lang.AssertionError -->
          <reporter-output>
          </reporter-output>
        </test-method> <!-- testContactCreationWithValidData -->
        <test-method status="FAIL" signature="testContactCreationWithValidData(com.example.tests.ContactData)[pri:0, instance:com.example.tests.ContactCreationTests@7c0e2abd]" name="testContactCreationWithValidData" duration-ms="4572" started-at="2016-12-29T13:57:55Z" data-provider="randomValidContactGenerator" finished-at="2016-12-29T13:57:59Z">
          <params>
            <param index="0">
              <value>
                <![CDATA[ContactData [firstname=contact-119201476]]]>
              </value>
            </param>
          </params>
          <exception class="java.lang.AssertionError">
            <message>
              <![CDATA[Lists differ at element [1]: ContactData [firstname=contact-119201476] != ContactData [firstname=contact-119201476 contact-411691808] expected [ContactData [firstname=contact-119201476]] but found [ContactData [firstname=contact-119201476 contact-411691808]]]]>
            </message>
            <full-stacktrace>
              <![CDATA[java.lang.AssertionError: Lists differ at element [1]: ContactData [firstname=contact-119201476] != ContactData [firstname=contact-119201476 contact-411691808] expected [ContactData [firstname=contact-119201476]] but found [ContactData [firstname=contact-119201476 contact-411691808]]
	at org.testng.Assert.fail(Assert.java:94)
	at org.testng.Assert.failNotEquals(Assert.java:496)
	at org.testng.Assert.assertEquals(Assert.java:125)
	at org.testng.Assert.assertEquals(Assert.java:551)
	at org.testng.Assert.assertEquals(Assert.java:516)
	at com.example.tests.ContactCreationTests.testContactCreationWithValidData(ContactCreationTests.java:75)
	at sun.reflect.NativeMethodAccessorImpl.invoke0(Native Method)
	at sun.reflect.NativeMethodAccessorImpl.invoke(Unknown Source)
	at sun.reflect.DelegatingMethodAccessorImpl.invoke(Unknown Source)
	at java.lang.reflect.Method.invoke(Unknown Source)
	at org.testng.internal.MethodInvocationHelper.invokeMethod(MethodInvocationHelper.java:85)
	at org.testng.internal.Invoker.invokeMethod(Invoker.java:639)
	at org.testng.internal.Invoker.invokeTestMethod(Invoker.java:816)
	at org.testng.internal.Invoker.invokeTestMethods(Invoker.java:1124)
	at org.testng.internal.TestMethodWorker.invokeTestMethods(TestMethodWorker.java:125)
	at org.testng.internal.TestMethodWorker.run(TestMethodWorker.java:108)
	at org.testng.TestRunner.privateRun(TestRunner.java:774)
	at org.testng.TestRunner.run(TestRunner.java:624)
	at org.testng.SuiteRunner.runTest(SuiteRunner.java:359)
	at org.testng.SuiteRunner.runSequentially(SuiteRunner.java:354)
	at org.testng.SuiteRunner.privateRun(SuiteRunner.java:312)
	at org.testng.SuiteRunner.run(SuiteRunner.java:261)
	at org.testng.SuiteRunnerWorker.runSuite(SuiteRunnerWorker.java:52)
	at org.testng.SuiteRunnerWorker.run(SuiteRunnerWorker.java:86)
	at org.testng.TestNG.runSuitesSequentially(TestNG.java:1215)
	at org.testng.TestNG.runSuitesLocally(TestNG.java:1140)
	at org.testng.TestNG.run(TestNG.java:1048)
	at org.testng.remote.AbstractRemoteTestNG.run(AbstractRemoteTestNG.java:132)
	at org.testng.remote.RemoteTestNG.initAndRun(RemoteTestNG.java:236)
	at org.testng.remote.RemoteTestNG.main(RemoteTestNG.java:81)
]]>
            </full-stacktrace>
          </exception> <!-- java.lang.AssertionError -->
          <reporter-output>
          </reporter-output>
        </test-method> <!-- testContactCreationWithValidData -->
        <test-method status="FAIL" signature="testContactCreationWithValidData(com.example.tests.ContactData)[pri:0, instance:com.example.tests.ContactCreationTests@7c0e2abd]" name="testContactCreationWithValidData" duration-ms="4457" started-at="2016-12-29T13:57:59Z" data-provider="randomValidContactGenerator" finished-at="2016-12-29T13:58:04Z">
          <params>
            <param index="0">
              <value>
                <![CDATA[ContactData [firstname=contact-1626331660]]]>
              </value>
            </param>
          </params>
          <exception class="java.lang.AssertionError">
            <message>
              <![CDATA[Lists differ at element [3]: ContactData [firstname=contact-1626331660] != ContactData [firstname=contact-1626331660 contact-2039470173] expected [ContactData [firstname=contact-1626331660]] but found [ContactData [firstname=contact-1626331660 contact-2039470173]]]]>
            </message>
            <full-stacktrace>
              <![CDATA[java.lang.AssertionError: Lists differ at element [3]: ContactData [firstname=contact-1626331660] != ContactData [firstname=contact-1626331660 contact-2039470173] expected [ContactData [firstname=contact-1626331660]] but found [ContactData [firstname=contact-1626331660 contact-2039470173]]
	at org.testng.Assert.fail(Assert.java:94)
	at org.testng.Assert.failNotEquals(Assert.java:496)
	at org.testng.Assert.assertEquals(Assert.java:125)
	at org.testng.Assert.assertEquals(Assert.java:551)
	at org.testng.Assert.assertEquals(Assert.java:516)
	at com.example.tests.ContactCreationTests.testContactCreationWithValidData(ContactCreationTests.java:75)
	at sun.reflect.NativeMethodAccessorImpl.invoke0(Native Method)
	at sun.reflect.NativeMethodAccessorImpl.invoke(Unknown Source)
	at sun.reflect.DelegatingMethodAccessorImpl.invoke(Unknown Source)
	at java.lang.reflect.Method.invoke(Unknown Source)
	at org.testng.internal.MethodInvocationHelper.invokeMethod(MethodInvocationHelper.java:85)
	at org.testng.internal.Invoker.invokeMethod(Invoker.java:639)
	at org.testng.internal.Invoker.invokeTestMethod(Invoker.java:816)
	at org.testng.internal.Invoker.invokeTestMethods(Invoker.java:1124)
	at org.testng.internal.TestMethodWorker.invokeTestMethods(TestMethodWorker.java:125)
	at org.testng.internal.TestMethodWorker.run(TestMethodWorker.java:108)
	at org.testng.TestRunner.privateRun(TestRunner.java:774)
	at org.testng.TestRunner.run(TestRunner.java:624)
	at org.testng.SuiteRunner.runTest(SuiteRunner.java:359)
	at org.testng.SuiteRunner.runSequentially(SuiteRunner.java:354)
	at org.testng.SuiteRunner.privateRun(SuiteRunner.java:312)
	at org.testng.SuiteRunner.run(SuiteRunner.java:261)
	at org.testng.SuiteRunnerWorker.runSuite(SuiteRunnerWorker.java:52)
	at org.testng.SuiteRunnerWorker.run(SuiteRunnerWorker.java:86)
	at org.testng.TestNG.runSuitesSequentially(TestNG.java:1215)
	at org.testng.TestNG.runSuitesLocally(TestNG.java:1140)
	at org.testng.TestNG.run(TestNG.java:1048)
	at org.testng.remote.AbstractRemoteTestNG.run(AbstractRemoteTestNG.java:132)
	at org.testng.remote.RemoteTestNG.initAndRun(RemoteTestNG.java:236)
	at org.testng.remote.RemoteTestNG.main(RemoteTestNG.java:81)
]]>
            </full-stacktrace>
          </exception> <!-- java.lang.AssertionError -->
          <reporter-output>
          </reporter-output>
        </test-method> <!-- testContactCreationWithValidData -->
        <test-method status="PASS" signature="tearDown()[pri:0, instance:com.example.tests.ContactCreationTests@7c0e2abd]" name="tearDown" is-config="true" duration-ms="1128" started-at="2016-12-29T13:58:04Z" finished-at="2016-12-29T13:58:05Z">
          <reporter-output>
          </reporter-output>
        </test-method> <!-- tearDown -->
      </class> <!-- com.example.tests.ContactCreationTests -->
    </test> <!-- Default test -->
  </suite> <!-- Default suite -->
</testng-results>
